Workbook

Sheet Primarios
A1: Device Name:
A2: Device Description:
A3: Serial Number:
A4: Device ID:
A5: Ubication | C5: Posición 1 | D5: Posición 2 | E5: Posición 3 | F5: Posición 4 | G5: Posición 5 | H5: Posición 6 | I5: Posición 7 | J5: Posición 8 | K5: Posición 9 | M5: Posición 1 | N5: Posición 2 | O5: Posición 3 | P5: Posición 4 | Q5: Posición 5 | R5: Posición 6 | S5: Posición 7 | T5: Posición 8 | U5: Posición 9
A6: Sample | B6: Date and Time | C6: Temperature (°C) | D6: Temperature (°C) | E6: Temperature (°C) | F6: Temperature (°C) | G6: Temperature (°C) | H6: Temperature (°C) | I6: Temperature (°C) | J6: Temperature (°C) | K6: Temperature (°C) | M6: Humedad (% RH) | N6: Humedad (% RH) | O6: Humedad (% RH) | P6: Humedad (% RH) | Q6: Humedad (% RH) | R6: Humedad (% RH) | S6: Humedad (% RH) | T6: Humedad (% RH) | U6: Humedad (% RH)
A7: 1
A8: 2
A9: 3
A10: 4
A11: 5
A12: 6
A13: 7
A14: 8
A15: 9
A16: 10
A17: 11
A18: 12
... A295: 289

Sheet PalisadeFitLinks
A1: Num Links | B1: 2
A2: =_xll.FitLink(#REF!,14921,11128,1) -> #NAME?
A3: =_xll.FitLink(#REF!,14921,90620,1) -> #NAME?

Sheet T
A1: ANALISIS CALIFICACIÓN OPERACIONAL- ESTABILIDAD DEL CALOR
A3: =Análisis!A2 -> Empresa: | C3: =Análisis!C2 -> 0 | E3: Hora de inicio de calificación: | G3: =C17 -> 0 | H3: =G3 -> 0
A4: =Análisis!A3 -> Marca: | C4: =Análisis!C3 -> 0 | E4: Hora final de calificación: | G4: =C305 -> 0 | H4: =G4 -> 0
A5: =Análisis!A4 -> Ubicación: | C5: =Análisis!C4 -> 0 | E5: Muestra estadistica (datos): | G5: =COUNT(D17:I305) -> 1734
A6: =Análisis!A5 -> Código de interno: | C6: =Análisis!C5 -> 0 | E6: Frecuencia de muestreo | G6: 5 minutos
A7: =Análisis!A6 -> Rango de temperatura: | C7: =Análisis!C6 -> 0 | E7: Tiempo de muestreo | G7: 24 horas
A10: Device Name: | D10: =Primarios!C1 -> 0 | E10: =Primarios!D1 -> 0 | F10: =Primarios!E1 -> 0 | G10: =Primarios!F1 -> 0 | H10: =Primarios!G1 -> 0 | I10: =Primarios!H1 -> 0 | J10: =Primarios!I1 -> 0 | K10: =Primarios!J1 -> 0 | L10: =Primarios!K1 -> 0
A11: Device Description: | D11: =Primarios!C2 -> 0 | E11: =Primarios!D2 -> 0 | F11: =Primarios!E2 -> 0 | G11: =Primarios!F2 -> 0 | H11: =Primarios!G2 -> 0 | I11: =Primarios!H2 -> 0 | J11: =Primarios!I2 -> 0 | K11: =Primarios!J2 -> 0 | L11: =Primarios!K2 -> 0
A12: Serial Number: | D12: =Primarios!C3 -> 0 | E12: =Primarios!D3 -> 0 | F12: =Primarios!E3 -> 0 | G12: =Primarios!F3 -> 0 | H12: =Primarios!G3 -> 0 | I12: =Primarios!H3 -> 0 | J12: =Primarios!I3 -> 0 | K12: =Primarios!J3 -> 0 | L12: =Primarios!K3 -> 0
A13: Device ID: | D13: =Primarios!C4 -> 0 | E13: =Primarios!D4 -> 0 | F13: =Primarios!E4 -> 0 | G13: =Primarios!F4 -> 0 | H13: =Primarios!G4 -> 0 | I13: =Primarios!H4 -> 0 | J13: =Primarios!I4 -> 0 | K13: =Primarios!J4 -> 0 | L13: =Primarios!K4 -> 0
A14: Ubicación | D14: =Primarios!C5 -> Posición 1 | E14: =Primarios!D5 -> Posición 2 | F14: =Primarios!E5 -> Posición 3 | G14: =Primarios!F5 -> Posición 4 | H14: =Primarios!G5 -> Posición 5 | I14: =Primarios!H5 -> Posición 6 | J14: =Primarios!I5 -> Posición 7 | K14: =Primarios!J5 -> Posición 8 | L14: =Primarios!K5 -> Posición 9
A15: Cronometro (min) | B15: Sample Number | C15: Date and Time (UTC-05:00) | D15: =Primarios!C6 -> Temperature (°C) | E15: =Primarios!D6 -> Temperature (°C) | F15: =Primarios!E6 -> Temperature (°C) | G15: =Primarios!F6 -> Temperature (°C) | H15: =Primarios!G6 -> Temperature (°C) | I15: =Primarios!H6 -> Temperature (°C) | J15: =Primarios!I6 -> Temperature (°C) | K15: =Primarios!J6 -> Temperature (°C) | L15: =Primarios!K6 -> Temperature (°C)
A17: 0 | B17: =Primarios!A7 -> 1 | C17: =Primarios!B7 -> 0 | D17: =Primarios!C7 -> 0 | E17: =Primarios!D7 -> 0 | F17: =Primarios!E7 -> 0 | G17: =Primarios!F7 -> 0 | H17: =Primarios!G7 -> 0 | I17: =Primarios!H7 -> 0 | ... L17: =Primarios!K7 -> 0
A18: 0.0034722222 | B18: =Primarios!A8 -> 2 | C18: =Primarios!B8 -> 0 | D18: =Primarios!C8 -> 0 | E18: =Primarios!D8 -> 0 | F18: =Primarios!E8 -> 0 | G18: =Primarios!F8 -> 0 | H18: =Primarios!G8 -> 0 | I18: =Primarios!H8 -> 0 | ... L18: =Primarios!K8 -> 0
A19: 0.0069444444 | B19: =Primarios!A9 -> 3 | C19: =Primarios!B9 -> 0 | D19: =Primarios!C9 -> 0 | E19: =Primarios!D9 -> 0 | F19: =Primarios!E9 -> 0 | G19: =Primarios!F9 -> 0 | H19: =Primarios!G9 -> 0 | I19: =Primarios!H9 -> 0 | ... L19: =Primarios!K9 -> 0
A20: 0.010416667 | B20: =Primarios!A10 -> 4 | C20: =Primarios!B10 -> 0 | D20: =Primarios!C10 -> 0 | E20: =Primarios!D10 -> 0 | F20: =Primarios!E10 -> 0 | G20: =Primarios!F10 -> 0 | H20: =Primarios!G10 -> 0 | I20: =Primarios!H10 -> 0 | ... L20: =Primarios!K10 -> 0
A21: 0.013888889 | B21: =Primarios!A11 -> 5 | C21: =Primarios!B11 -> 0 | D21: =Primarios!C11 -> 0 | E21: =Primarios!D11 -> 0 | F21: =Primarios!E11 -> 0 | G21: =Primarios!F11 -> 0 | H21: =Primarios!G11 -> 0 | I21: =Primarios!H11 -> 0 | ... L21: =Primarios!K11 -> 0
A22: 0.017361111 | B22: =Primarios!A12 -> 6 | C22: =Primarios!B12 -> 0 | D22: =Primarios!C12 -> 0 | E22: =Primarios!D12 -> 0 | F22: =Primarios!E12 -> 0 | G22: =Primarios!F12 -> 0 | H22: =Primarios!G12 -> 0 | I22: =Primarios!H12 -> 0 | ... L22: =Primarios!K12 -> 0
A23: 0.020833333 | B23: =Primarios!A13 -> 7 | C23: =Primarios!B13 -> 0 | D23: =Primarios!C13 -> 0 | E23: =Primarios!D13 -> 0 | F23: =Primarios!E13 -> 0 | G23: =Primarios!F13 -> 0 | H23: =Primarios!G13 -> 0 | I23: =Primarios!H13 -> 0 | ... L23: =Primarios!K13 -> 0
A24: 0.024305556 | B24: =Primarios!A14 -> 8 | C24: =Primarios!B14 -> 0 | D24: =Primarios!C14 -> 0 | E24: =Primarios!D14 -> 0 | F24: =Primarios!E14 -> 0 | G24: =Primarios!F14 -> 0 | H24: =Primarios!G14 -> 0 | I24: =Primarios!H14 -> 0 | ... L24: =Primarios!K14 -> 0
A25: 0.027777778 | B25: =Primarios!A15 -> 9 | C25: =Primarios!B15 -> 0 | D25: =Primarios!C15 -> 0 | E25: =Primarios!D15 -> 0 | F25: =Primarios!E15 -> 0 | G25: =Primarios!F15 -> 0 | H25: =Primarios!G15 -> 0 | I25: =Primarios!H15 -> 0 | ... L25: =Primarios!K15 -> 0
A26: 0.03125 | B26: =Primarios!A16 -> 10 | C26: =Primarios!B16 -> 0 | D26: =Primarios!C16 -> 0 | E26: =Primarios!D16 -> 0 | F26: =Primarios!E16 -> 0 | G26: =Primarios!F16 -> 0 | H26: =Primarios!G16 -> 0 | I26: =Primarios!H16 -> 0 | ... L26: =Primarios!K16 -> 0
A27: 0.034722222 | B27: =Primarios!A17 -> 11 | C27: =Primarios!B17 -> 0 | D27: =Primarios!C17 -> 0 | E27: =Primarios!D17 -> 0 | F27: =Primarios!E17 -> 0 | G27: =Primarios!F17 -> 0 | H27: =Primarios!G17 -> 0 | I27: =Primarios!H17 -> 0 | ... L27: =Primarios!K17 -> 0
A28: 0.038194444 | B28: =Primarios!A18 -> 12 | C28: =Primarios!B18 -> 0 | D28: =Primarios!C18 -> 0 | E28: =Primarios!D18 -> 0 | F28: =Primarios!E18 -> 0 | G28: =Primarios!F18 -> 0 | H28: =Primarios!G18 -> 0 | I28: =Primarios!H18 -> 0 | ... L28: =Primarios!K18 -> 0
... A305: 1 | B305: =Primarios!A295 -> 289 | C305: =Primarios!B295 -> 0 | D305: =Primarios!C295 -> 0 | E305: =Primarios!D295 -> 0 | F305: =Primarios!E295 -> 0 | G305: =Primarios!F295 -> 0 | H305: =Primarios!G295 -> 0 | I305: =Primarios!H295 -> 0 | ... L305: =Primarios!K295 -> 0
B306: TEMPERATURA MÁXIMA | D306: =MAX(D17:D305) -> 0 | E306: =MAX(E17:E305) -> 0 | F306: =MAX(F17:F305) -> 0 | G306: =MAX(G17:G305) -> 0 | H306: =MAX(H17:H305) -> 0 | I306: =MAX(I17:I305) -> 0 | J306: =MAX(J17:J305) -> 0 | K306: =MAX(K17:K305) -> 0 | L306: =MAX(L17:L305) -> 0
B307: TEMPERATURA MÍNIMA | D307: =MIN(D17:D305) -> 0 | E307: =MIN(E17:E305) -> 0 | F307: =MIN(F17:F305) -> 0 | G307: =MIN(G17:G305) -> 0 | H307: =MIN(H17:H305) -> 0 | I307: =MIN(I17:I305) -> 0 | J307: =MIN(J17:J305) -> 0 | K307: =MIN(K17:K305) -> 0 | L307: =MIN(L17:L305) -> 0
B308: TEMPERATURA PROMEDIO | D308: =ROUND(AVERAGE(D17:D305),2) -> 0 | E308: =ROUND(AVERAGE(E17:E305),2) -> 0 | F308: =ROUND(AVERAGE(F17:F305),2) -> 0 | G308: =ROUND(AVERAGE(G17:G305),2) -> 0 | H308: =ROUND(AVERAGE(H17:H305),2) -> 0 | I308: =ROUND(AVERAGE(I17:I305),2) -> 0 | J308: =ROUND(AVERAGE(J17:J305),2) -> 0 | K308: =ROUND(AVERAGE(K17:K305),2) -> 0 | L308: =ROUND(AVERAGE(L17:L305),2) -> 0
B309: DISTRUBUCION | D309: =$D$311-D308 -> 0 | E309: =$D$311-E308 -> 0 | F309: =$D$311-F308 -> 0 | G309: =$D$311-G308 -> 0 | H309: =$D$311-H308 -> 0 | I309: =$D$311-I308 -> 0 | J309: =$D$311-J308 -> 0 | K309: =$D$311-K308 -> 0 | L309: =$D$311-L308 -> 0
B311: TEMPERATURA PROMEDIO | D311: =ROUND(AVERAGE(D308:L308),2) -> 0
B312: TEMPERATURA MINIMA | D312: =MIN(D307:L307) -> 0
B313: TEMPERATURA MAXIMA | D313: =MAX(D306:L306) -> 0
B316: ANALISIS ESTADISTICO
B318: Numero de recolectores | C318: Estudio de reproducibilidad (intervalo de confiabilidad del 95%) | F318: intervalo 95%
C319: s | D319: LMD 95% | E319: x
B320: n | F320: inf | G320: sup
B321: =COUNT(D308:L308) -> 9 | C321: =STDEV(D308:L308) -> 0 | D321: =CONFIDENCE(0.05,C321,B321) -> #NUM! | E321: =ROUND(AVERAGE(D308:L308),2) -> 0 | F321: =E321-D321 -> #NUM! | G321: =E321+D321 -> #NUM!

Sheet Fallas Tem
A1: Device Name: | C1: =Primarios!C1 -> 0
A2: Device Description: | C2: =Primarios!C2 -> 0 | G2: Corte de energía
A3: Serial Number: | C3: =Primarios!C3 -> 0 | G3: Recuperación
A4: Device ID: | C4: =Primarios!C4 -> 0
C5: =Primarios!C5 -> Posición 1
A6: Sample Number | B6: Date and Time (UTC-05:00) | C6: Temperature (°C)
A7: 1
A8: 2
A9: 3
A10: 4
A11: 5
A12: 6
A13: 7
A14: 8
A15: 9
A16: 10
A17: 11
A18: 12
... A66: 60

Sheet HR
A1: ANALISIS CALIFICACIÓN OPERACIONAL- HUMEDAD RELATIVA
A3: =Análisis!A2 -> Empresa: | C3: =Análisis!C2 -> 0 | E3: Hora de inicio de calificación: | G3: =C17 -> 0 | H3: =G3 -> 0
A4: =Análisis!A3 -> Marca: | C4: =Análisis!C3 -> 0 | E4: Hora final de calificación: | G4: =C305 -> 0 | H4: =G4 -> 0
A5: =Análisis!A4 -> Ubicación: | C5: =Análisis!C4 -> 0 | E5: Muestra estadistica (datos): | G5: =COUNT(D17:I305) -> 1734
A6: =Análisis!A5 -> Código de interno: | C6: =Análisis!C5 -> 0 | E6: Frecuencia de muestreo | G6: 5 minutos
A7: =Análisis!A6 -> Rango de temperatura: | C7: =Análisis!D6 -> 0 | E7: Tiempo de muestreo | G7: 24 horas
A10: Device Name: | D10: =Primarios!M1 -> 0 | E10: =Primarios!N1 -> 0 | F10: =Primarios!O1 -> 0 | G10: =Primarios!P1 -> 0 | H10: =Primarios!Q1 -> 0 | I10: =Primarios!R1 -> 0 | J10: =Primarios!S1 -> 0 | K10: =Primarios!T1 -> 0 | L10: =Primarios!U1 -> 0
A11: Device Description: | D11: =Primarios!M2 -> 0 | E11: =Primarios!N2 -> 0 | F11: =Primarios!O2 -> 0 | G11: =Primarios!P2 -> 0 | H11: =Primarios!Q2 -> 0 | I11: =Primarios!R2 -> 0 | J11: =Primarios!S2 -> 0 | K11: =Primarios!T2 -> 0 | L11: =Primarios!U2 -> 0
A12: Serial Number: | D12: =Primarios!M3 -> 0 | E12: =Primarios!N3 -> 0 | F12: =Primarios!O3 -> 0 | G12: =Primarios!P3 -> 0 | H12: =Primarios!Q3 -> 0 | I12: =Primarios!R3 -> 0 | J12: =Primarios!S3 -> 0 | K12: =Primarios!T3 -> 0 | L12: =Primarios!U3 -> 0
A13: Device ID: | D13: =Primarios!M4 -> 0 | E13: =Primarios!N4 -> 0 | F13: =Primarios!O4 -> 0 | G13: =Primarios!P4 -> 0 | H13: =Primarios!Q4 -> 0 | I13: =Primarios!R4 -> 0 | J13: =Primarios!S4 -> 0 | K13: =Primarios!T4 -> 0 | L13: =Primarios!U4 -> 0
A14: Ubicación | D14: =Primarios!M5 -> Posición 1 | E14: =Primarios!N5 -> Posición 2 | F14: =Primarios!O5 -> Posición 3 | G14: =Primarios!P5 -> Posición 4 | H14: =Primarios!Q5 -> Posición 5 | I14: =Primarios!R5 -> Posición 6 | J14: =Primarios!S5 -> Posición 7 | K14: =Primarios!T5 -> Posición 8 | L14: =Primarios!U5 -> Posición 9
A15: Cronometro (min) | B15: Sample Number | C15: Date and Time (UTC-05:00) | D15: =Primarios!M6 -> Humedad (% RH) | E15: =Primarios!N6 -> Humedad (% RH) | F15: =Primarios!O6 -> Humedad (% RH) | G15: =Primarios!P6 -> Humedad (% RH) | H15: =Primarios!Q6 -> Humedad (% RH) | I15: =Primarios!R6 -> Humedad (% RH) | J15: =Primarios!S6 -> Humedad (% RH) | K15: =Primarios!T6 -> Humedad (% RH) | L15: =Primarios!U6 -> Humedad (% RH)
A17: 0 | B17: =Primarios!A7 -> 1 | C17: =Primarios!B7 -> 0 | D17: =Primarios!M7 -> 0 | E17: =Primarios!N7 -> 0 | F17: =Primarios!O7 -> 0 | G17: =Primarios!P7 -> 0 | H17: =Primarios!Q7 -> 0 | I17: =Primarios!R7 -> 0 | J17: =Primarios!S7 -> 0 | K17: =Primarios!T7 -> 0 | L17: =Primarios!U7 -> 0
A18: 0.0034722222 | B18: =Primarios!A8 -> 2 | C18: =Primarios!B8 -> 0 | D18: =Primarios!M8 -> 0 | E18: =Primarios!N8 -> 0 | F18: =Primarios!O8 -> 0 | G18: =Primarios!P8 -> 0 | H18: =Primarios!Q8 -> 0 | I18: =Primarios!R8 -> 0 | J18: =Primarios!S8 -> 0 | K18: =Primarios!T8 -> 0 | L18: =Primarios!U8 -> 0
A19: 0.0069444444 | B19: =Primarios!A9 -> 3 | C19: =Primarios!B9 -> 0 | D19: =Primarios!M9 -> 0 | E19: =Primarios!N9 -> 0 | F19: =Primarios!O9 -> 0 | G19: =Primarios!P9 -> 0 | H19: =Primarios!Q9 -> 0 | I19: =Primarios!R9 -> 0 | J19: =Primarios!S9 -> 0 | K19: =Primarios!T9 -> 0 | L19: =Primarios!U9 -> 0
A20: 0.010416667 | B20: =Primarios!A10 -> 4 | C20: =Primarios!B10 -> 0 | D20: =Primarios!M10 -> 0 | E20: =Primarios!N10 -> 0 | F20: =Primarios!O10 -> 0 | G20: =Primarios!P10 -> 0 | H20: =Primarios!Q10 -> 0 | I20: =Primarios!R10 -> 0 | J20: =Primarios!S10 -> 0 | K20: =Primarios!T10 -> 0 | L20: =Primarios!U10 -> 0
A21: 0.013888889 | B21: =Primarios!A11 -> 5 | C21: =Primarios!B11 -> 0 | D21: =Primarios!M11 -> 0 | E21: =Primarios!N11 -> 0 | F21: =Primarios!O11 -> 0 | G21: =Primarios!P11 -> 0 | H21: =Primarios!Q11 -> 0 | I21: =Primarios!R11 -> 0 | J21: =Primarios!S11 -> 0 | K21: =Primarios!T11 -> 0 | L21: =Primarios!U11 -> 0
A22: 0.017361111 | B22: =Primarios!A12 -> 6 | C22: =Primarios!B12 -> 0 | D22: =Primarios!M12 -> 0 | E22: =Primarios!N12 -> 0 | F22: =Primarios!O12 -> 0 | G22: =Primarios!P12 -> 0 | H22: =Primarios!Q12 -> 0 | I22: =Primarios!R12 -> 0 | J22: =Primarios!S12 -> 0 | K22: =Primarios!T12 -> 0 | L22: =Primarios!U12 -> 0
A23: 0.020833333 | B23: =Primarios!A13 -> 7 | C23: =Primarios!B13 -> 0 | D23: =Primarios!M13 -> 0 | E23: =Primarios!N13 -> 0 | F23: =Primarios!O13 -> 0 | G23: =Primarios!P13 -> 0 | H23: =Primarios!Q13 -> 0 | I23: =Primarios!R13 -> 0 | J23: =Primarios!S13 -> 0 | K23: =Primarios!T13 -> 0 | L23: =Primarios!U13 -> 0
A24: 0.024305556 | B24: =Primarios!A14 -> 8 | C24: =Primarios!B14 -> 0 | D24: =Primarios!M14 -> 0 | E24: =Primarios!N14 -> 0 | F24: =Primarios!O14 -> 0 | G24: =Primarios!P14 -> 0 | H24: =Primarios!Q14 -> 0 | I24: =Primarios!R14 -> 0 | J24: =Primarios!S14 -> 0 | K24: =Primarios!T14 -> 0 | L24: =Primarios!U14 -> 0
A25: 0.027777778 | B25: =Primarios!A15 -> 9 | C25: =Primarios!B15 -> 0 | D25: =Primarios!M15 -> 0 | E25: =Primarios!N15 -> 0 | F25: =Primarios!O15 -> 0 | G25: =Primarios!P15 -> 0 | H25: =Primarios!Q15 -> 0 | I25: =Primarios!R15 -> 0 | J25: =Primarios!S15 -> 0 | K25: =Primarios!T15 -> 0 | L25: =Primarios!U15 -> 0
A26: 0.03125 | B26: =Primarios!A16 -> 10 | C26: =Primarios!B16 -> 0 | D26: =Primarios!M16 -> 0 | E26: =Primarios!N16 -> 0 | F26: =Primarios!O16 -> 0 | G26: =Primarios!P16 -> 0 | H26: =Primarios!Q16 -> 0 | I26: =Primarios!R16 -> 0 | J26: =Primarios!S16 -> 0 | K26: =Primarios!T16 -> 0 | L26: =Primarios!U16 -> 0
A27: 0.034722222 | B27: =Primarios!A17 -> 11 | C27: =Primarios!B17 -> 0 | D27: =Primarios!M17 -> 0 | E27: =Primarios!N17 -> 0 | F27: =Primarios!O17 -> 0 | G27: =Primarios!P17 -> 0 | H27: =Primarios!Q17 -> 0 | I27: =Primarios!R17 -> 0 | J27: =Primarios!S17 -> 0 | K27: =Primarios!T17 -> 0 | L27: =Primarios!U17 -> 0
A28: 0.038194444 | B28: =Primarios!A18 -> 12 | C28: =Primarios!B18 -> 0 | D28: =Primarios!M18 -> 0 | E28: =Primarios!N18 -> 0 | F28: =Primarios!O18 -> 0 | G28: =Primarios!P18 -> 0 | H28: =Primarios!Q18 -> 0 | I28: =Primarios!R18 -> 0 | J28: =Primarios!S18 -> 0 | K28: =Primarios!T18 -> 0 | L28: =Primarios!U18 -> 0
... A305: 1 | B305: =Primarios!A295 -> 289 | C305: =Primarios!B295 -> 0 | D305: =Primarios!M295 -> 0 | E305: =Primarios!N295 -> 0 | F305: =Primarios!O295 -> 0 | G305: =Primarios!P295 -> 0 | H305: =Primarios!Q295 -> 0 | I305: =Primarios!R295 -> 0 | J305: =Primarios!S295 -> 0 | K305: =Primarios!T295 -> 0 | L305: =Primarios!U295 -> 0
B306: TEMPERATURA MÁXIMA | D306: =MAX(D17:D305) -> 0 | E306: =MAX(E17:E305) -> 0 | F306: =MAX(F17:F305) -> 0 | G306: =MAX(G17:G305) -> 0 | H306: =MAX(H17:H305) -> 0 | I306: =MAX(I17:I305) -> 0 | J306: =MAX(J17:J305) -> 0 | K306: =MAX(K17:K305) -> 0 | L306: =MAX(L17:L305) -> 0
B307: TEMPERATURA MÍNIMA | D307: =MIN(D17:D305) -> 0 | E307: =MIN(E17:E305) -> 0 | F307: =MIN(F17:F305) -> 0 | G307: =MIN(G17:G305) -> 0 | H307: =MIN(H17:H305) -> 0 | I307: =MIN(I17:I305) -> 0 | J307: =MIN(J17:J305) -> 0 | K307: =MIN(K17:K305) -> 0 | L307: =MIN(L17:L305) -> 0
B308: TEMPERATURA PROMEDIO | D308: =ROUND(AVERAGE(D17:D305),1) -> 0 | E308: =ROUND(AVERAGE(E17:E305),1) -> 0 | F308: =ROUND(AVERAGE(F17:F305),1) -> 0 | G308: =ROUND(AVERAGE(G17:G305),1) -> 0 | H308: =ROUND(AVERAGE(H17:H305),1) -> 0 | I308: =ROUND(AVERAGE(I17:I305),1) -> 0 | J308: =ROUND(AVERAGE(J17:J305),1) -> 0 | K308: =ROUND(AVERAGE(K17:K305),1) -> 0 | L308: =ROUND(AVERAGE(L17:L305),1) -> 0
B309: DISTRUBUCION | D309: =$D$311-D308 -> 0 | E309: =$D$311-E308 -> 0 | F309: =$D$311-F308 -> 0 | G309: =$D$311-G308 -> 0 | H309: =$D$311-H308 -> 0 | I309: =$D$311-I308 -> 0 | J309: =$D$311-J308 -> 0 | K309: =$D$311-K308 -> 0 | L309: =$D$311-L308 -> 0
B311: TEMPERATURA PROMEDIO | D311: =ROUND(AVERAGE(D308:L308),1) -> 0
B312: TEMPERATURA MINIMA | D312: =MIN(D307:L307) -> 0
B313: TEMPERATURA MAXIMA | D313: =MAX(D306:L306) -> 0
B316: ANALISIS ESTADISTICO
B318: Numero de recolectores | C318: Estudio de reproducibilidad (intervalo de confiabilidad del 95%) | F318: intervalo 95%
C319: s | D319: LMD 95% | E319: x
B320: n | F320: inf | G320: sup
B321: =COUNT(D308:L308) -> 9 | C321: =STDEV(D308:L308) -> 0 | D321: =CONFIDENCE(0.05,C321,B321) -> #NUM! | E321: =ROUND(AVERAGE(D308:L308),2) -> 0 | F321: =E321-D321 -> #NUM! | G321: =E321+D321 -> #NUM!

Sheet Fallas HR 
A1: Device Name: | C1: =Primarios!M1 -> 0
A2: Device Description: | C2: =Primarios!M2 -> 0 | G2: Corte de energía
A3: Serial Number: | C3: =Primarios!M3 -> 0 | G3: Recuperación
A4: Device ID: | C4: =Primarios!M4 -> 0
C5: =Primarios!M5 -> Posición 1
A6: Sample Number | B6: Date and Time (UTC-05:00) | C6: =Primarios!S6 -> Humedad (% RH)
A7: 1
A8: 2
A9: 3
A10: 4
A11: 5
A12: 6
A13: 7
A14: 8
A15: 9
A16: 10
A17: 11
A18: 12
... A66: 60

Sheet Análisis
A1: Protocolo: Operacional- Cámara climática
A2: Empresa:
A3: Marca:
A4: Ubicación:
A5: Código de interno:
A6: Rango de temperatura:
A7: Rango de humedad relativa:
A8: Fecha calificación: | C8: =T!C17 -> 0
A9: Fecha re-calificación: | C9: =C8+365 -> 365
A11: Tabla 1: Ciclos realizados y recolectores utilizados
A13: Fecha - Hora | C13: Recolectores (+)
A14: Inicial | B14: Final | C14: Ubicación | D14: =Primarios!C5 -> Posición 1 | E14: =Primarios!D5 -> Posición 2 | F14: =Primarios!E5 -> Posición 3 | G14: =Primarios!F5 -> Posición 4 | H14: =Primarios!G5 -> Posición 5 | I14: =Primarios!H5 -> Posición 6 | J14: =Primarios!I5 -> Posición 7 | K14: =Primarios!J5 -> Posición 8 | L14: =Primarios!K5 -> Posición 9
A15: =T!H3 -> 0 | B15: =T!H4 -> 0 | C15: Serial | D15: =Primarios!C3 -> 0 | E15: =Primarios!D3 -> 0 | F15: =Primarios!E3 -> 0 | G15: =Primarios!F3 -> 0 | H15: =Primarios!G3 -> 0 | I15: =Primarios!H3 -> 0 | J15: =Primarios!I3 -> 0 | K15: =Primarios!J3 -> 0 | L15: =Primarios!K3 -> 0
A16: =T!G3 -> 0 | B16: =T!G4 -> 0 | D16: (++)
A19: Tabla 2: Distribución de la temperatura | G19: Tabla 3: Distribución de la humedad relativa
A21: Recolector | B21: Temperatura (°C) | D21: Cumple | E21: Rango | G21: Recolector | H21: Humedad relativa (%) | J21: Cumple | K21: Rango
B22: Media del recolector | C22: Diferencia | D22: Si/No | E22: Si/No | H22: Media del recolector | I22: Diferencia | J22: Si/No | K22: Si/No
A23: =D15 -> 0 | B23: =T!D308 -> 0 | C23: =B$32-B23 -> 0 | D23: =IF(ABS(C23)<2,"SI","NO") -> SI | E23: =IF(B23>($C$6-2),(IF(B23<($C$6+2),"SI","NO2")),"NO1") -> SI | G23: =A23 -> 0 | H23: =HR!D308 -> 0 | I23: =H$32-H23 -> 0 | J23: =IF(ABS(I23)<5,"SI","NO") -> SI | K23: =IF(H23>($C$7-5),(IF(H23<($C$7+5),"SI","NO2")),"NO1") -> SI
A24: =E15 -> 0 | B24: =T!E308 -> 0 | C24: =B$32-B24 -> 0 | D24: =IF(ABS(C24)<2,"SI","NO") -> SI | E24: =IF(B24>($C$6-2),(IF(B24<($C$6+2),"SI","NO2")),"NO1") -> SI | G24: =A24 -> 0 | H24: =HR!E308 -> 0 | I24: =H$32-H24 -> 0 | J24: =IF(ABS(I24)<5,"SI","NO") -> SI | K24: =IF(H24>($C$7-5),(IF(H24<($C$7+5),"SI","NO2")),"NO1") -> SI
A25: =F15 -> 0 | B25: =T!F308 -> 0 | C25: =B$32-B25 -> 0 | D25: =IF(ABS(C25)<2,"SI","NO") -> SI | E25: =IF(B25>($C$6-2),(IF(B25<($C$6+2),"SI","NO2")),"NO1") -> SI | G25: =A25 -> 0 | H25: =HR!F308 -> 0 | I25: =H$32-H25 -> 0 | J25: =IF(ABS(I25)<5,"SI","NO") -> SI | K25: =IF(H25>($C$7-5),(IF(H25<($C$7+5),"SI","NO2")),"NO1") -> SI
A26: =G15 -> 0 | B26: =T!G308 -> 0 | C26: =B$32-B26 -> 0 | D26: =IF(ABS(C26)<2,"SI","NO") -> SI | E26: =IF(B26>($C$6-2),(IF(B26<($C$6+2),"SI","NO2")),"NO1") -> SI | G26: =A26 -> 0 | H26: =HR!G308 -> 0 | I26: =H$32-H26 -> 0 | J26: =IF(ABS(I26)<5,"SI","NO") -> SI | K26: =IF(H26>($C$7-5),(IF(H26<($C$7+5),"SI","NO2")),"NO1") -> SI
A27: =H15 -> 0 | B27: =T!H308 -> 0 | C27: =B$32-B27 -> 0 | D27: =IF(ABS(C27)<2,"SI","NO") -> SI | E27: =IF(B27>($C$6-2),(IF(B27<($C$6+2),"SI","NO2")),"NO1") -> SI | G27: =A27 -> 0 | H27: =HR!H308 -> 0 | I27: =H$32-H27 -> 0 | J27: =IF(ABS(I27)<5,"SI","NO") -> SI | K27: =IF(H27>($C$7-5),(IF(H27<($C$7+5),"SI","NO2")),"NO1") -> SI
A28: =I15 -> 0 | B28: =T!I308 -> 0 | C28: =B$32-B28 -> 0 | D28: =IF(ABS(C28)<2,"SI","NO") -> SI | E28: =IF(B28>($C$6-2),(IF(B28<($C$6+2),"SI","NO2")),"NO1") -> SI | G28: =A28 -> 0 | H28: =HR!I308 -> 0 | I28: =H$32-H28 -> 0 | J28: =IF(ABS(I28)<5,"SI","NO") -> SI | K28: =IF(H28>($C$7-5),(IF(H28<($C$7+5),"SI","NO2")),"NO1") -> SI
A29: =J15 -> 0 | B29: =T!J308 -> 0 | C29: =B$32-B29 -> 0 | D29: =IF(ABS(C29)<2,"SI","NO") -> SI | E29: =IF(B29>($C$6-2),(IF(B29<($C$6+2),"SI","NO2")),"NO1") -> SI | G29: =A29 -> 0 | H29: =HR!J308 -> 0 | I29: =H$32-H29 -> 0 | J29: =IF(ABS(I29)<5,"SI","NO") -> SI | K29: =IF(H29>($C$7-5),(IF(H29<($C$7+5),"SI","NO2")),"NO1") -> SI
A30: =K15 -> 0 | B30: =T!K308 -> 0 | C30: =B$32-B30 -> 0 | D30: =IF(ABS(C30)<2,"SI","NO") -> SI | E30: =IF(B30>($C$6-2),(IF(B30<($C$6+2),"SI","NO2")),"NO1") -> SI | G30: =A30 -> 0 | H30: =HR!K308 -> 0 | I30: =H$32-H30 -> 0 | J30: =IF(ABS(I30)<5,"SI","NO") -> SI | K30: =IF(H30>($C$7-5),(IF(H30<($C$7+5),"SI","NO2")),"NO1") -> SI
A31: =L15 -> 0 | B31: =T!L308 -> 0 | C31: =B$32-B31 -> 0 | D31: =IF(ABS(C31)<2,"SI","NO") -> SI | E31: =IF(B31>($C$6-2),(IF(B31<($C$6+2),"SI","NO2")),"NO1") -> SI | G31: =A31 -> 0 | H31: =HR!L308 -> 0 | I31: =H$32-H31 -> 0 | J31: =IF(ABS(I31)<5,"SI","NO") -> SI | K31: =IF(H31>($C$7-5),(IF(H31<($C$7+5),"SI","NO2")),"NO1") -> SI
A32: Temperatura promedio | B32: =T!D311 -> 0 | G32: Humedad relativa promedio | H32: =HR!D311 -> 0
A35: Tabla 4: Evaluación dinámica del controlador de temperatura
A37: Tcontrol (°C) | B37: Trecolector ( ºC) | E37: Diferencia | G37: cumple
B38: Tmed | C38: Tmin | D38: Tmax | E38: min (-) | F38: max (+) | G38: (si/no)
A39: =C6 -> 0 | B39: =T!D311 -> 0 | C39: =T!D312 -> 0 | D39: =T!D313 -> 0 | E39: =A39-C39 -> 0 | F39: =D39-A39 -> 0 | G39: =IF(ABS(E39)<2,IF(ABS(F39<2),"SI","NO"),"NO") -> SI
A40: HRcontrol (%) | B40: HRrecolector (%) | E40: Diferencia | G40: cumple
B41: HRmed | C41: HRmin | D41: HRmax | E41: min (-) | F41: max (+) | G41: (si/no)
A42: =C7 -> 0 | B42: =HR!D311 -> 0 | C42: =HR!D312 -> 0 | D42: =HR!D313 -> 0 | E42: =A42-C42 -> 0 | F42: =D42-A42 -> 0 | G42: =IF(ABS(E42)<5,IF(ABS(F42<5),"SI","NO"),"NO") -> SI
A45: Tabla 5: Evaluación dinámica del termo higrómetro
A47: Temperatura (ºC ) | C47: Diferencia (-) | D47: Cumple
A48: Recolectores (^) | B48: Lectura del equipo (Lc) | C48: (C ) | D48: (si/no)
A49: =B23 -> 0 | C49: =B49-A49 -> 0 | D49: =IF(ABS(C49)<1,"SI","NO") -> SI
A50: Humedad relativa (%) | C50: Diferencia (-) | D50: Cumple
A51: Recolectores (^) | B51: Lectura del equipo (Lc) | C51: (%) | D51: (si/no)
...
